Workbook

Sheet Overview
A1: PEMS - Platform Overview
A3: Read this sheet first, before Read Me / Instructions / Backlog, in any new session. It is the fastest orientation to what PEMS is, where it is going and how work is done here. Update it whenever something it describes goes stale (not only Instructions/Memory).
A5: What PEMS is
A6: PEMS is an enterprise .NET system (ASP.NET Core MVC/Razor + EF Core 10 + SQL Server) for engineering and maintenance management in the oil and petrochemical industry: EDMS/VDR, CMMS/EAM, permit to work (PTW), inventory, production, reliability and local AI (Ollama/OCR). Today it is a set of fixed modules (98 controllers, 91 View folders, 116 migrations, 1,403 tests). PEMS is a brand-new product whose long-term aim is to become the single platform for its customers' engineering and maintenance processes.
A8: New direction: from fixed software to a dynamic BPMS
A9: Forms, modules and workflows must be fully creatable and editable by authorized users, with no coding and no build/deploy. Today's fixed modules are progressively converted into metadata definitions (strangler pattern, backlog area MIG) and specialized parts (AI, OCR, EDMS revision engine, reliability) stay as Domain Packs with extension points. Shared engines: metadata registry, form, workflow, rules, access/RLS, events, reporting.
A11: Commercial model
A12: For now, an on-prem licence locked to the machine and the install time: even if a whole machine is imaged and deployed elsewhere it must not work. Process: a request file from the customer server, returned to the vendor, a signed licence file issued, installed. Licence types: lifetime, term (a time period), trial, demo. Details in the Licensing Design sheet and the LIC area. The product never calls out (production has no internet); the website and the demo are the only online parts.
A14: Prioritization rule of this backlog
A15: Priority is set by 'ability to sell' and 'dynamic core': P0 = without it nothing can be sold or the dynamic platform cannot form (foundation decisions, metadata, grid/form, licensing, RLS, demo, install); P1 = needed for commercial release 1.0; P2 = competitive/next stage; P3 = later. The legacy domain backlog (CMMS/EDMS etc.) matters but stays behind sales and dynamicization work unless it blocks them.
A17: Current state (estimated from code, no build executed)
A18: Strengths: domain breadth, modern authentication (Identity + FIDO2), a central access model, a workflow runtime, local AI. Main gaps: no App/Entity/Form registry and no form builder; no workflow studio; no licensing and no installer; no server-side session registry; no Jalali UI; default culture is en. No build/test has been run (row F_BASE). Database creation, install and update are fully code-first (migrator + Admin Database Update page, 2026-10-22).
... A24: 'Is X done / status of Y?' -> Backlog (Evidence column). 'What is next?' -> Roadmap. 'Which rules always apply?' -> Instructions. 'What do we know from earlier platforms?' -> Lessons. 'Which capabilities must PEMS offer?' -> Capability Checklist. 'How does licensing work?' -> Licensing Design. 'What is supported and up to which limits?' -> Supportability Matrix. 'What happened to an old task?' -> Old to New Map.

Sheet Read Me
A1: PEMS - Backlog & Roadmap (rebuilt edition)
A2: Created 2026-10-15 from the static PEMS audit plus lessons and capabilities of a reference platform. The filename is deliberately date-free and the file is updated in place.
A4: Sheets
A5: Sheet | B5: Purpose
A6: Overview | B6: Orientation - read first.
A7: Read Me | B7: This sheet: column guide, statuses, priorities.
A8: Instructions | B8: Standing rules applied in every task.
A9: Backlog | B9: The unified task list (source of truth).
A10: Test Plan | B10: QA cases for Done rows and for P0 rows after implementation.
A11: Roadmap | B11: Milestones and execution order.
A12: Supportability Matrix | B12: What is supported (capabilities, limits, platforms, versions) - updated in every finished task.
A13: Licensing Design | B13: Machine/install-locked licensing design and threat table.
A14: Capability Checklist | B14: Capabilities PEMS must offer, sourced from the reference platform.
A15: Lessons | B15: Durable lessons and facts (reference platform and PEMS).
A16: Old to New Map | B16: Mapping of every old backlog row to the new rows.
A17: Summary | B17: Automatic counts (formulas) over the Backlog.
A19: Backlog columns
A20: Column | B20: Meaning
A21: # | B21: Permanent number; never reused.
A22: Doer | B22: Claude = doable in a code session; User = decision or legal/commercial/operational work of the owner.
A23: Area | B23: Work area.
A24: Track | B24: Feature, Bug Fix, Tech Debt, Decision Needed, Library Modernization, Research, Docs, Legal/Business, Ops Process.
A25: Status | B25: Not Started, In Progress, Partial, Done, Hold (decided but paused by the PM until released), Later (deliberately deferred, kept in the backlog), Cancelled, Obsolete. Done only with evidence.
A26: Confirmed by PM | B26: Yes when the owner/PM has reviewed and confirmed the row (its scope, priority and milestone); No until then. Only the PM sets this flag; automated updates of this file preserve what the PM entered.
A27: Sprint | B27: Sprint the row is planned in (Sprint 1, Sprint 1 stretch); empty = backlog. The Sprint 1 sheet has goal, capacity and the committed list.
A28: Owner | B28: Accountable person for the row in a sprint (Member A / Member B until names are mapped); the doer may still be the assistant.
A29: Group | B29: Related tasks grouped into one workstream; filter on this column to see and decide a whole group together.
A30: Priority | B30: P0 sales blocker/dynamic core, P1 needed for commercial 1.0, P2 competitive, P3 later.
A31: Evidence | B31: What was seen in code/documents today (or a known pitfall).
... A40: Old Ref | B40: Related row in the old audit (OLD-n) or OLD-Dn for existing capabilities.
A42: Components and versions (bill of materials)
A43: Component | B43: Version / status
A44: PEMS (system) | B44: No official version defined - action: F_CI
A45: PEMS.Web / Application / Domain / Persistence / WorkflowPlatform / AI | B45: .NET 10 SDK, EF Core 10.0.10
A46: Workbook | B46: 1.2 - 2026-10-22 (English edition; lives in the repository at plan/PEMS_Backlog_Roadmap.xlsx)
A48: Priorities
A49: Priority | B49: Definition
A50: P0 | B50: Sales blocker or dynamic core - nothing proceeds without it
A51: P1 | B51: Needed for commercial release 1.0
A52: P2 | B52: Competitive / next stage
...

Sheet Instructions
A1: Standing instructions for the PEMS project
A2: Apply these in every task even when the request does not restate them. Keep in sync with Memory; a rule changes only with the owner's decision.
A4: # | B4: Rule | C4: Description
A5: 1 | B5: Offline execution | C5: Production has no internet: no CDN, external call, telemetry or online licence/update check is allowed in the product. Any new library must run fully offline and not depend on an online source at build time. (The website and demo are online parts and are separate from the product.)
A6: 2 | B6: Library-first, with licence control | C6: Before hand-building (expression engine, grid, workflow designer, rules, scheduler, PDF/Excel) check for a mature library. For commercial sale every library licence (copyleft, revenue thresholds, mandatory watermark) must be recorded in row L_OSS; an unsuitable library is replaced. Custom code only with a stated reason.
A7: 3 | B7: Engines once, not per module | C7: Each shared capability (metadata, forms, workflow, access/RLS, events, reporting, licensing) has exactly one implementation; modules call it. Parallel concepts are forbidden.
A8: 4 | B8: No new static modules | C8: From now on a new module is built first as metadata (form/view/workflow). If that is impossible, record the reason and the needed extension point in an ADR. A new static module without this record is not allowed.
A9: 5 | B9: Persian-first, English file | C9: The product default language is Persian with RTL; displayed dates are Jalali with Gregorian/UTC storage. This workbook, code identifiers and ADRs are written in English.
A10: 6 | B10: Go forward, not backward-compatible | C10: During development applied migrations are not edited; always add a new numbered migration/seed. No backward-compatibility shim unless a live customer needs it.
A11: 7 | B11: Task workflow | C11: Before starting set the row to In Progress; afterwards commit separately with a version bump and CHANGELOG, then update Status/Report in this file as its own commit. Message format 'vX.Y.Z: description'. Never use 'git add -A'; stage only specific files.
A12: 8 | B12: Order of work: scope, plan, design, implement | C12: (a) Everything the user said, including later clarifications; (b) update the backlog row before designing; (c) then design library-first with best practice; (d) then implement.
A13: 9 | B13: Three version numbers | C13: System = CalVer (YYYY.MM.PATCH); components = SemVer; editing this file does not change a version. The component table is on the Read Me sheet.
A14: 10 | B14: Secrets and keys | C14: No real secret, key or connection string in the repo or release package. The licence-signing private key and the reset private key are created and used only on the owner computers (Hamid's and Saber's own) and are never in the repo, on a CI or shared server, or in the assistant's environment (L_KEYS).
A15: 11 | B15: Licence active everywhere | C15: Licence checks apply in all environments (a signed dev licence); no bypass flag may reach any package. Always-free surfaces come only from an allowlist (L_FREE).
A16: 12 | B16: Central RLS | C16: No data path (list, search, report, export, API, AI) is without the central RLS filter; direct role-based checks are not allowed.
... A32: 28 | B32: Study existing tasks before adding one | C32: Owner decision 2026-10-26: before adding a task (backlog row and Jira issue) read the existing ones - search the backlog and Jira by area, files, goal and keywords, including Done and Hold rows. If an existing task covers the work or can absorb it, modify that task (extend What to do / Done when, update the workbook row, the Jira issue and a comment saying what changed and why) instead of adding a new one. Add a new row only when no task fits, and name the tasks that were checked in its Evidence. A new row keeps the next free Plan ID; held (Hold) tasks count as not open.

Sheet Backlog
A1: # | B1: Doer | C1: Area | D1: Task | E1: Track | F1: Status | G1: Priority | H1: Evidence | I1: Prompt | J1: Requirement | K1: Report | L1: Milestone | M1: Effort | N1: Commercial | O1: Depends | P1: Reference (Titan) | Q1: Old Ref | R1: Group | S1: Confirmed by PM | T1: Sprint | U1: Owner
A2: 1 | B2: Claude | C2: Foundation, Architecture Decisions & Baseline | D2: Run the build and test suite once and store a baseline report (counts, duration, environment, every failing test) | E2: Tech Debt | F2: Not Started | G2: P0 | H2: The previous audit was static only; no real build or test run exists. About 1,403 Fact/Theory tests exist but their pass/fail state is unknown. | I2: 1) On a clean checkout run dotnet restore, build and test for PEMS.slnx with a reachable SQL Server (LocalDB or SQL Express) and PEMS_TEST_CONNECTION set. 2) Store the console output and a summary under plan/baseline/ (date, SDK and SQL versions, pass/fail/skip counts, duration). 3) List every failing test with its cause: pre-existing, environment, or real defect. 4) Create one backlog row per real defect. | J2: Done when: plan/baseline/<date>.md exists with the numbers above; each failing test is listed with a cause; each real defect has its own backlog row. Known today (not yet in a report): LinuxDeploymentArtifactsTests LF check, a SQLEXPRESS-only sidebar test and ImportCenterNavigationTests (LetterCompose) fail on a clean main. | L2: M0 | M2: S | N2: High | Q2: OLD-1 | R2: Foundation & decisions | S2: No | T2: Sprint 1 | U2: Member B
A3: 2 | B3: Claude | C3: Foundation, Architecture Decisions & Baseline | D3: Create the architecture decision record (ADR) log in plan/adr and record the decisions already taken | E3: Docs | F3: Not Started | G3: P0 | H3: Key decisions (dynamic storage, UI stack, licensing, libraries) are not written down; they are scattered across Role/ documents. | I3: 1) Add plan/adr/TEMPLATE.md (context, decision, alternatives, consequences, status, date, decided by). 2) Write one ADR each for: hybrid storage (#4), Razor plus a separate PEMS.UI library (#5, docs/design/COMPONENT_LIBRARY_PLAN.md), code-first database (#309), environment and secrets files (#315), licensing threat model and VM policy (#96, #97), demo branch policy (#300). 3) Link each ADR from the backlog row it explains. | J3: Done when: plan/adr contains the template and six ADRs approved by Member A; every backlog row marked decided points to its ADR. | K3: Added plan/adr: TEMPLATE.md, README index and ADR-0001..0006 (hybrid storage, Razor + PEMS.UI, code-first database, env/secrets files, licensing threat model + VM policy, demo/staging branch policy), each linked from its explaining doc. Merged in atapems-tech/PEMS#4. Approved by Member A (Hamid Maleki) 2026-10-27. No Supportability Matrix change. | L3: M0 | M3: S | N3: High | Q3: OLD-2 | R3: Foundation & decisions | S3: No | T3: Sprint 1 | U3: Member A
A4: 3 | B4: Claude | C4: Foundation, Architecture Decisions & Baseline | D4: Write the one-page platform operating model: what is the dynamic engine, what are Domain Packs, what stays static | E4: Docs | F4: Not Started | G4: P0 | H4: Today PEMS is a set of fixed MVC modules (98 controllers, 91 View folders). The boundary between shared engines and domain code is not written down. | I4: 1) Classify every existing capability (the 98 controllers; use docs/design/ui-pattern-audit.csv and the Capability Checklist sheet) as engine, domain pack or permanently static. 2) Define the extension points a pack may use (actions, widgets, validators, views) and what a pack may never change. 3) Draw the layer diagram (engine, packs, UI library, licensing). Output: docs/architecture/PLATFORM_OPERATING_MODEL.md. | J4: Done when: Member A approved the document; every module appears in exactly one class; rows #10, #85 and #94 reference it. | L4: M0 | M4: M | N4: Sales blocker | Q4: OLD-3 | R4: Foundation & decisions | S4: No | T4: Sprint 1 | U4: Member A
A5: 4 | B5: User | C5: Foundation, Architecture Decisions & Baseline | D5: Storage for user-created entities (decided: hybrid - real tables for user-built entities, JSON column for custom fields on existing entities) | E5: Decision Needed | F5: Done | G5: P0 | H5: Options: (a) real SQL tables via guided DDL, (b) JSON column plus indexed computed columns, (c) EAV. PEMS runs on EF Core 10 + SQL Server. | I5: Benchmark all three with a small prototype (100k records, filter/sort/report). Initial recommendation: hybrid, with real tables for fully user-defined entities and a JSON column for custom fields on existing static entities. | J5: An approved ADR with performance criteria, migration cost, reporting impact and effect on RLS and audit. | K5: Decided 2026-10-18: hybrid - real SQL tables for fully user-built entities, one JSON column for custom fields on existing entities. Prototype validation happens in D_DDL/D_SCHEMA; ADR to be written under F_ADR. ADR: plan/adr/0001-hybrid-storage-for-user-built-entities.md | L5: M0 | M5: M | N5: Sales blocker | P5: Titan #17 #61 | R5: Foundation & decisions | S5: Yes
A6: 5 | B6: User | C6: Foundation, Architecture Decisions & Baseline | D6: UI layer for reusable components (decided: Razor plus a reusable component library, designers as embedded JavaScript components) | E6: Decision Needed | F6: Done | G6: P0 | H6: The current UI is Razor + Bootstrap + jQuery with 225 views and page-specific JS/CSS (pems-data-grid.js etc.). Options: ViewComponent/TagHelper + Web Components, Blazor, or an SPA hosted inside the app. | I6: Compare the three options with a vertical slice (grid + form). Criteria: fully offline without CDN, RTL, form-builder velocity, upgrade path from existing Razor. | J6: An approved ADR; all CMP_* and FRM_* work is defined against it. | K6: Decided 2026-10-18: keep Razor and build a reusable component library, with the form/workflow designers as embedded JavaScript components. ADR to be written under F_ADR. 2026-10-23: refined in docs/design/COMPONENT_LIBRARY_PLAN.md - separate Razor Class Library PEMS.UI (decided); canonical technology recommended as descriptor-driven static Razor components with an MVC Tag Helper facade, gated by spike #319 (the vertical-slice comparison this row asked for was never run). ADR: plan/adr/0002-razor-with-separate-pems-ui-library.md (component technology D3 still open, spike #319) ADR-0001..0006 approved by Member A 2026-10-27. Component technology (D3): spike #319 run 2026-10-27, see ADR-0007 (proposed, static Razor components + Tag Helper facade). | L6: M0 | M6: M | N6: Sales blocker | P6: Titan #177 | R6: Foundation & decisions | S6: Yes
A7: 6 | B7: Claude | C7: Foundation, Architecture Decisions & Baseline | D7: Decision and evaluation of libraries (library-first) with license and offline checks | E7: Library Modernization | F7: Not Started | G7: P0 | H7: Building from scratch must be justified. Needs: expression engine (NCalc/DynamicExpresso), grid, workflow designer, rule/policy engine, scheduler. | I7: For each need compare at least two options on commercial license, fully offline operation, active maintenance and RTL support, and record the result. | J7: A library decision table with a column 'license suitable for commercial sale?'; no runtime dependency needs a CDN or internet. | L7: M0 | M7: M | N7: High | P7: Titan #7 #53 #62 | Q7: OLD-87 OLD-92 | R7: Foundation & decisions | S7: No
A8: 7 | B8: Claude | C8: Foundation, Architecture Decisions & Baseline | D8: Make the build workflow fail on red tests and publish a versioned artifact on version tags | E8: Feature | F8: Not Started | G8: P0 | H8: Owner requirement 2026-10-18: the demo is deployed from the demo branch of the product repository and the landing from its own repository. The product repository needs a reusable build-and-test workflow. There is no automated pipeline today; only a Dockerfile and docker-compose exist. | I8: 1) Use the baseline (#1) to decide which tests run on the hosted runner; remove continue-on-error from the test step. 2) Run on pushes and pull requests to main and demo. 3) On a tag vYYYY.MM.PATCH build the release package (deploy/Build-Package.ps1 or a container image) and attach it to a GitHub release with commit and build number. 4) Document it in docs/deployment. | J8: Done when: a red test fails the workflow; a tag produces a release artifact with version, commit and build number; no secret is stored in the repository. | K8: PM 2026-10-18: basic CI first; no dependency on the workflow foundation. | L8: M0 | M8: M | N8: High | O8: #1 | P8: Titan #119 | R8: DevOps & release | S8: Yes | T8: Sprint 1 | U8: Member B
A9: 8 | B9: Claude | C9: Foundation, Architecture Decisions & Baseline | D9: Repository cleanup: stray folders and duplicate documents (.claude/Role vs .github/Role) | E9: Tech Debt | F9: Not Started | G9: P2 | H9: The root contains WebApplication1, 'New Text Document.txt' and two identical copies of the Role documents under .claude and .github. 2026-10-28 plan audit: dependency/milestone corrected (see docs/audits/2026-10-28-dynamic-restful-audit.md). | I9: Remove or archive anything unused and pick one official location for the Role documents. | J9: The repo builds without unused folders and the Role documents have one official home. | L9: M1 | M9: S | N9: Low | R9: Foundation & decisions | S9: No
A10: 9 | B10: Claude | C10: Foundation, Architecture Decisions & Baseline | D10: Audit the repository, history and container files for secrets and unsafe defaults, and fix what remains | E10: Bug Fix | F10: Not Started | G10: P0 | H10: Default connection strings or keys inside source are a sales blocker. appsettings.json/UAT/Development in PEMS.Web have not been reviewed. | I10: 1) Confirm HEAD has no secret (env files done in #315; check docker-compose.yml, Dockerfile, workflows, scripts). 2) Search the git history for secrets that were ever committed (for example the old default admin password and any connection strings) and list them. 3) For each finding record: fixed, needs rotation (give to #317), or accepted. Output: docs/audits/SECRETS_AUDIT_2026-10.md. | J10: Done when: the report exists; HEAD is clean; every historical finding has a decision and an owner. | K10: Merged 2026-10-26 (PR atapems-tech/PEMS#6, merge bc717dc): HEAD and full history (202 commits, all refs) scanned; no tokens, keys or real connection strings; five built-in passwords found and removed from HEAD (default administrator, employee-created users, compose SQL sa fallback, load-test accounts, weak example); rotation list and runbook handed to #317; held follow-ups #374 and #375; open items in docs/audits/SECRETS_AUDIT_2026-10.md. Tests NOT run (no .NET SDK): the row is Done only after the build and the new tests pass. | L10: M0 | M10: S | N10: Sales blocker | P10: Titan #137 | R10: Foundation & decisions | S10: No | T10: Sprint 1 | U10: Member B
A11: 10 | B11: Claude | C11: Metadata Core & Dynamic Platform | D11: Registry for apps/modules/entities/fields/relations with versioning | E11: Feature | F11: Not Started | G11: P0 | H11: PEMS has no general App/Entity/Field registry (audit E1/E2). The proven pattern is that everything is a database row, not code. 2026-10-28: design in docs/architecture/METADATA_REGISTRY_DESIGN.md (ADR-0010); payload and lifecycle follow the definition envelope. | I11: Design and build the metadata model (App, Module, Entity, Field, Relation, OptionSet, View, Form, Menu, StatusSet) with Draft/Published/Retired states. | J11: A sample entity is created, published and used for CRUD purely through metadata rows (no new C# code); metadata changes apply without build/redeploy. | L11: M1 | M11: XL | N11: Sales blocker | O11: #4 #3 | P11: Titan #61 | Q11: OLD-4 OLD-5 OLD-6 | R11: Dynamic data core | S11: No
A12: 11 | B12: Claude | C12: Metadata Core & Dynamic Platform | D12: Field type catalog: text, number, decimal, date (Jalali/Gregorian), boolean, single/multi select, lookup, user, file, rich text, computed, auto-number, JSON | E12: Feature | F12: Not Started | G12: P0 | H12: A single type definition from day one avoids the field-type vs column-type duplication seen in comparable platforms. 2026-10-28: design in docs/architecture/METADATA_REGISTRY_DESIGN.md (ADR-0010); payload and lifecycle follow the definition envelope. | I12: For every type define storage, validation, form/grid rendering, filtering, sorting, import/export and localization. | J12: A 'type x (storage/form/grid/filter/export)' matrix is complete and covered by automated tests. | L12: M1 | M12: L | N12: Sales blocker | O12: #10 | P12: Titan #19 | R12: Dynamic data core | S12: No
A13: 12 | B13: Claude | C13: Metadata Core & Dynamic Platform | D13: Generic dynamic CRUD/Query API with server-side paging, filter, sort and mandatory RLS | E13: Feature | F13: Not Started | G13: P0 | H13: Server-side paging above ~1,000 rows regressed twice on a comparable platform; one query contract from the start is required. 2026-10-28: REST inventory done, see docs/audits/REST_INVENTORY_2026-10-28.md and rest-inventory.csv (#432). | I13: Build one /api/d/{entity} endpoint with a single query contract (page/sort/filter/search/columns) used by every list and relation list. Route shape, paging style and error format come from the REST ADR (#431), not from this row; the first version must pass the API quality gates (#436). | J13: Test: 500k records, filter+sort under 500 ms; a record outside the user's access never appears in results or counts. The route and contract follow the REST API standard (#431): resource-oriented URLs instead of verbs, ETag/If-Match, RFC 9457 errors, OpenAPI. | L13: M1 | M13: XL | N13: Sales blocker | O13: #10 #11 #178 #431 #435 | P13: Titan #49 #136 | Q13: OLD-89 OLD-20 | R13: Dynamic data core | S13: No
A14: 13 | B14: Claude | C14: Metadata Core & Dynamic Platform | D14: Safe schema-change planner: add/delete/change field type with impact preview, approval and rollback | E14: Feature | F14: Not Started | G14: P0 | H14: Changing a field type on live data is the riskiest operation of any dynamic platform. 2026-10-28: design in docs/architecture/METADATA_REGISTRY_DESIGN.md (ADR-0010); payload and lifecycle follow the definition envelope. | I14: Generate a change plan: affected row count, data-loss risk, generated SQL, automatic backup and rollback path. | J14: Unsafe changes are blocked without two-step approval; rollback test on sample data succeeds. | L14: M1 | M14: XL | N14: Sales blocker | O14: #10 | P14: Titan #17 | Q14: OLD-88 | R14: Dynamic data core | S14: No
A15: 14 | B15: Claude | C15: Metadata Core & Dynamic Platform | D15: Physical storage generator (DDL) and JSON extension column for custom fields on static entities | E15: Feature | F15: Not Started | G15: P0 | H15: Customers must add a field to a static entity such as Equipment or WorkOrder without a code migration. | I15: Per the storage ADR: create/alter tables, indexes and foreign keys; store custom fields in a JSON column with computed indexes for filtering. | J15: A custom field added to Equipment in the UI, with no deploy, appears in list/form/export/search. | L15: M1 | M15: L | N15: Sales blocker | O15: #13 | R15: Dynamic data core | S15: No
A16: 15 | B16: Claude | C16: Metadata Core & Dynamic Platform | D16: Shared expression/formula engine for computed fields, validation and conditions | E16: Library Modernization | F16: Not Started | G16: P0 | H16: One formula engine should drive automatic values and validation; today each module has its own logic. | I16: Select an expression library (F_LIBS) and sandbox it: Jalali date functions, Persian text, relation lookups, time and memory limits. | J16: The same expression yields the same result on client, server and reports; a malicious expression (infinite loop) is stopped. | L16: M1 | M16: L | N16: High | O16: #6 | P16: Titan #12 | R16: Dynamic data core | S16: No
A17: 16 | B17: Claude | C17: Metadata Core & Dynamic Platform | D17: Configurable auto-numbering (pattern, Jalali/Gregorian year, periodic reset) with DB-enforced uniqueness | E17: Feature | F17: Partial | G17: P1 | H17: A serial that is sequential but not unique in the DB is a known defect pattern. Engineering documents and work orders need traceable numbers. | I17: Patterns such as WO-{YYYY}-{#####}; atomic allocation with DB locking and a unique index. | J17: A 50-parallel-request test yields no duplicate numbers; the pattern is editable and versioned. | K17: 2026-10-28 SCRUM-40: patterns per document type (NumberingSchemes, Admin > Numbering: tokens YYYY/YY Jalali or Gregorian, PROJECT, DISC, SEQ; yearly or no reset; manual entry flag; version + audit) applied to all procurement documents (MR, package, tender, bid, PO, contract); atomic counter per scope, existing numbers skipped, 50-parallel SQL test without duplicates. Other modules (work order, IRN, ...) still use the built-in formats. | L17: M4 | M17: M | N17: High | O17: #10 | P17: Titan #16 | R17: Dynamic data core | S17: No
A18: 17 | B18: Claude | C18: Metadata Core & Dynamic Platform | D18: Generic change audit (field-level history) for every dynamic entity | E18: Feature | F18: Not Started | G18: P0 | H18: Current audit covers access only (AuthorizationAuditLog). Selling to oil/petrochemical requires per-field change history. | I18: On every create/update/delete record who, when, before/after value and form/metadata version; show in a History tab. | J18: Each record's history is viewable, filterable and exportable and cannot be deleted manually. | L18: M1 | M18: L | N18: High | O18: #12 | Q18: OLD-58 | R18: Dynamic data core | S18: No
A19: 18 | B19: Claude | C19: Metadata Core & Dynamic Platform | D19: Concurrency control: optimistic rowversion plus live edit lock showing the lock holder | E19: Feature | F19: Not Started | G19: P1 | H19: PEMS has SignalR hubs but no generic record lock. Real-time and locking is a new subsystem, not an extension. 2026-10-28: follows the REST API standard ADR-0009 / guideline chapter 08 (#431). | I19: Locks with safe expiry, release on disconnect, auditable conflicts. | J19: Two users on one record: the second sees 'being edited by ...'; simultaneous saves never silently overwrite. | L19: M4 | M19: L | N19: Medium | O19: #12 | P19: Titan #104 | Q19: OLD-93 | R19: Dynamic data core | S19: No
A20: 19 | B20: Claude | C20: Metadata Core & Dynamic Platform | D20: Generic attachments, comments and activity (chatter) for any entity | E20: Feature | F20: Not Started | G20: P1 | H20: Each module has its own attachments/comments today; one shared component and model is needed. | I20: A polymorphic attachment/comment table whose RLS is inherited from the parent record, using the hardened upload path. | J20: One checkbox on an entity turns attachments/comments on. | L20: M4 | M20: M | N20: High | O20: #12 #183 | R20: Dynamic data core | S20: No
A21: 20 | B21: Claude | C21: Metadata Core & Dynamic Platform | D21: Menu generation from metadata with access filtering and orphan-controller test | E21: Feature | F21: Not Started | G21: P0 | H21: The current menu in _SidebarMenu.cshtml is static. 2026-10-28 audit: the designer saves through the definition store API (#434), not its own storage. 2026-10-28: the stored shape follows ADR-0011 (UI definition model). | I21: Tree menu from metadata (order, icon, grouping, license/access conditions); automated test for controllers with no menu entry. | J21: The menu updates with no code change when a module is added; items without permission are not shown. | K21: PM 2026-10-18: raised to P0/M2 (module wizard depends on it). | L21: M2 | M21: M | N21: High | O21: #10 #434 | Q21: OLD-7 | R21: Dynamic data core | S21: Yes
A22: 21 | B22: Claude | C22: Metadata Core & Dynamic Platform | D22: Managed Reference/OptionSet type: value lists with history and translation | E22: Feature | F22: Not Started | G22: P1 | H22: Selectable values must be translatable and carry history. | I22: OptionSet with value/label (Persian and English)/color/active flag and cascading dependencies (e.g. unit to equipment). | J22: Changing a value's label is correct on existing records and is audited. | L22: M4 | M22: M | N22: Medium | O22: #10 | P22: Titan #138 #230 | R22: Dynamic data core | S22: No
A23: 22 | B23: Claude | C23: Metadata Core & Dynamic Platform | D23: Relation registry and generalized Relationship Explorer with RLS on every node and edge | E23: Feature | F23: Not Started | G23: P1 | H23: PEMS already has a Relationship Explorer service (Done) but relations are hard-coded. | I23: Relations with cardinality, label, cascade, snapshot and permission; the relation graph is read from the registry. | J23: A relation added in the UI appears in the explorer and a forbidden node is never shown. | L23: M4 | M23: L | N23: High | O23: #10 | Q23: OLD-32 OLD-36 | R23: Dynamic data core | S23: No
A24: 23 | B24: Claude | C24: Metadata Core & Dynamic Platform | D24: Signed metadata package (export/import) and Dev-to-Test-to-Prod promotion | E24: Feature | F24: Not Started | G24: P0 | H24: Customers need to build modules/forms/workflows in test and promote them; without this dynamic behavior is unsafe in production. | I24: A JSON/zip package with dependencies, diff, approval, smoke test, release note and rollback. | J24: A module package installs on a second instance and runs untouched; an incompatible package is rejected. | K24: PM 2026-10-18: raised to P0/M2 (module versions depend on it). | L24: M2 | M24: L | N24: High | O24: #10 | P24: Titan #150 | Q24: OLD-75 | R24: Dynamic data core | S24: Yes
A25: 24 | B25: Claude | C25: Metadata Core & Dynamic Platform | D25: Multilingual labels and messages in metadata (translatable strings, Persian default + English) | E25: Feature | F25: Not Started | G25: P1 | H25: Language/direction should be configurable at system/app/model/field level. PEMS currently sets DefaultRequestCulture to en in Program.cs. | I25: All metadata labels as a language map with a defined fallback; Persian is the product default. | J25: Changing a user's language changes labels only, never data. | L25: M4 | M25: M | N25: High | O25: #10 #205 | P25: Titan #190 | R25: Dynamic data core | S25: No
A26: 25 | B26: Claude | C26: Metadata Core & Dynamic Platform | D26: Dynamic import designer (template, column mapping, staging, review, commit, rollback) on any entity | E26: Feature | F26: Not Started | G26: P1 | H26: PEMS has 11 fixed imports (Import Center). Customers must build imports for their own modules. A partial update must not fail on an intentionally blank field. | I26: Auto-generate an Excel template from metadata, error preview, asynchronous run and row-level error report. | J26: A 50k-row import with row-level errors and full rollback; import permission uses the same RLS. | L26: M4 | M26: L | N26: High | O26: #12 | P26: Titan #13 | Q26: OLD-56 OLD-57 | R26: Dynamic data core | S26: No
A27: 26 | B27: Claude | C27: Metadata Core & Dynamic Platform | D27: A field with a default value must never persist as NULL (including bulk paths) | E27: Tech Debt | F27: Not Started | G27: P2 | H27: Bulk and import paths bypass defaults on comparable platforms. | I27: Apply a DEFAULT constraint in the DB and enforce it in bulk/import paths. | J27: A bulk test shows no NULL for defaulted fields. | L27: M5 | M27: S | N27: Low | O27: #14 | P27: Titan #14 | R27: Dynamic data core | S27: No
A28: 27 | B28: Claude | C28: Metadata Core & Dynamic Platform | D28: Duplicate-record merge tool (pick the winning value per field, replace FKs, soft-delete the loser) | E28: Feature | F28: Not Started | G28: P3 | H28: Useful for cleaning migrated data. | I28: A merge wizard with preview and audit. | J28: Merging two duplicate equipment records moves every reference. | L28: M6 | M28: L | N28: Low | O28: #12 | P28: Titan #9 | R28: Dynamic data core | S28: No
A29: 28 | B29: Claude | C29: Metadata Core & Dynamic Platform | D29: Metadata cache with invalidation on write and ETag/gzip for static responses | E29: Tech Debt | F29: Not Started | G29: P0 | H29: A cached registry (TTL + write invalidation) with ETag/gzip cured slow database access on a comparable platform; a registry change must not need a rebuild. 2026-10-28: follows the REST API standard ADR-0009 / guideline chapter 08 (#431). 2026-10-28: design in docs/architecture/METADATA_REGISTRY_DESIGN.md (ADR-0010); payload and lifecycle follow the definition envelope. | I29: In-memory cache keyed by metadata version; coherent invalidation across instances. | J29: A metadata change takes effect on all instances in under 2 seconds; database load for reading metadata is near zero. | L29: M1 | M29: M | N29: High | O29: #10 | P29: Titan #50 #61 | R29: Dynamic data core | S29: No
A30: 29 | B30: Claude | C30: Component Library & Design System | D30: Finish the UI pattern audit: review the 30 heaviest pages by hand and compute the convertible percentage per migration wave | E30: Research | F30: Partial | G30: P0 | H30: Views are page-specific, with separate CSS/JS (pems-data-grid, pems-vdr, pems-global-search). No pattern inventory exists. 2026-10-23 static audit run (tools/UiAudit/pattern-audit.py): 339 views = 303 pages + 36 partials; list 141, form 61 (+20 small), dashboard 26, table-only 32, detail 10, other 13; 2,587 hand-written inputs vs 202 asp-for; 342 tables, 108 modals, 846 badges; 632 inline styles in 197 views, 89 inline scripts; only 33/303 pages use the page header, 8 an empty state, 3 a loading state. Per-view table 'view -> pattern -> target component -> wave' is docs/design/ui-pattern-audit.csv; summary docs/design/UI_PATTERN_AUDIT.md. | I30: 1) Open docs/design/UI_PATTERN_AUDIT.md and extend its heaviest-pages list to 30. 2) For each page decide A (convertible with the planned components as is), B (needs a new component) or C (stays custom); record the new components B needs. 3) Add the percentages per wave to the audit document. 4) Re-run python tools/UiAudit/pattern-audit.py --md and commit the refreshed files. | J30: Done when: the audit document lists A/B/C for 30 pages and the percentage per wave W1-W5; the list of missing components feeds rows #322-#325. | K30: Static inventory done; the 'convertible percentage' and manual review of the heaviest pages remain (rerun the script per wave). | L30: M0 | M30: M | N30: Sales blocker | Q30: OLD-96 | R30: UI component library | S30: No | T30: Sprint 1 | U30: Member B
A31: 30 | B31: Claude | C31: Component Library & Design System | D31: Consolidate the design tokens into one file and remove hard-coded colours from the shared CSS | E31: Feature | F31: Not Started | G31: P0 | H31: Foundation for white-labeling (BRD) and UI consistency; content density should be configurable. 2026-10-23 audit: 21 CSS files / 4,554 lines, 642 hard-coded hex colours vs 753 var(--pems-*) uses, 65 physical left/right rules (RTL); .vs-* workspace system and --pems tokens already exist and are the starting point. | I31: 1) Create PEMS.Web/wwwroot/css/tokens.css (moves into PEMS.UI later, #320) with colour, typography (Persian and English), spacing, radius, elevation, density, status and chart palette, for the Light, Dark and Turquoise themes. 2) Replace the 642 hex colours in the shared CSS (pems-workspace.css, pems-themes.css, site.css, administration-design-system.css) with tokens. 3) Replace physical left/right rules (65 in the audit) with logical properties. 4) Compare screenshots before and after in LTR and RTL. | J31: Done when: the four listed CSS files contain no hex colours and no physical left/right rules; screenshots show no visible change; the token file is documented in docs/design/WORKSPACE_DESIGN_SYSTEM.md. | L31: M1 | M31: M | N31: High | O31: #5 | P31: Titan #192 #128 | Q31: OLD-95 | R31: UI component library | S31: No | T31: Sprint 1 | U31: Member B
A32: 31 | B32: Claude | C32: Component Library & Design System | D32: Core component library: button, inputs, select/lookup, date/time, upload, modal, drawer, tabs, badge, tooltip, empty/error/loading states | E32: Feature | F32: Not Started | G32: P0 | H32: Buttons, chips and loading states must be unified under one API. 2026-10-23: decomposed into #322 fields/form shell, #323 data display and skeletons, #324 overlays/navigation, #325 page templates; project, contract and gates in #320, #321, #326, #327. | I32: Components with a consistent API, documented, with no inline styles. | J32: 100% of components in the form/grid vertical slice use only the library. | L32: M1 | M32: XL | N32: Sales blocker | O32: #30 #5 #320 #321 | P32: Titan #41 #121 #122 #244 | Q32: OLD-96 | R32: UI component library | S32: No
A33: 32 | B33: Claude | C33: Component Library & Design System | D33: Enterprise data grid: server-side paging, filter, saved views, column picker, pinning, bulk actions, export, density, virtualization | E33: Feature | F33: Not Started | G33: P0 | H33: The current grid (pems-data-grid.js) is page-specific. This is the most visible component in a sales demo. | I33: Build the grid on the D_API contract; RTL, 100k-row speed, per-user/role saved views. | J33: Every list in the vertical slice uses this grid and becomes interactive within 5 seconds. | L33: M1 | M33: XL | N33: Sales blocker | O33: #12 #31 | P33: Titan #53 #139 | Q33: OLD-97 OLD-90 | R33: UI component library | S33: No
A34: 33 | B34: Claude | C34: Component Library & Design System | D34: View types: list, tree, cards/gallery, Kanban/status board, calendar (Jalali+Gregorian), timeline/Gantt | E34: Feature | F34: Not Started | G34: P1 | H34: A calendar view available by default on every model is a proven need; CMMS scheduling depends on it. | I34: Each view is configured from entity metadata (date field, grouping). | J34: A dynamic entity gets a calendar/kanban view by toggling it, with no code. | L34: M4 | M34: L | N34: High | O34: #32 | P34: Titan #179 #36 | Q34: OLD-66 | R34: UI component library | S34: No
A35: 34 | B35: Claude | C35: Component Library & Design System | D35: Dynamic form component standards (sections, tabs, help text, conditional, attachments, drafts, dirty-state prompt, responsiveness) | E35: Feature | F35: Not Started | G35: P0 | H35: Foundation of FRM_RUN. | I35: Specify and build each form component with error, read-only and loading states. | J35: All states are visible and tested in the component gallery. | L35: M1 | M35: L | N35: High | O35: #31 | Q35: OLD-98 | R35: UI component library | S35: No
A36: 35 | B36: Claude | C36: Component Library & Design System | D36: Lookup/Relation picker and TreeSelect (unit, PBS, equipment) with server-side search | E36: Feature | F36: Partial | G36: P1 | H36: Parent selectors and tree selects must be library-based and optimized. | I36: Debounced search, paging, RLS, multi-select. | J36: Selecting from 200k equipment records is smooth. | K36: 2026-10-28 SCRUM-57: searchable select on every form (PEMS.UI pems-select.js on vendored Tom Select, loaded by the layout; >=8 options automatic, data-pems-select-source for permission-aware server search via /SearchApi, opt-out, inline in modals/dropdowns, cascading refresh, RTL/dark, fa/en). TreeSelect (unit/PBS) and paging beyond the first 20 server results are still open. | L36: M4 | M36: M | N36: High | O36: #12 #31 | P36: Titan #33 #47 | R36: UI component library | S36: No
A37: 36 | B37: Claude | C37: Component Library & Design System | D37: Workflow/status components: timeline, badge, action bar, delegation, escalation, comments, audit trail | E37: Feature | F37: Not Started | G37: P1 | H37: PEMS has static _PemsStageDiagram and _WorkOrderStagesDiagram. 2026-10-28 plan audit: dependency/milestone corrected (see docs/audits/2026-10-28-dynamic-restful-audit.md). | I37: Convert them to data-driven components fed by the workflow runtime. | J37: Every dynamic process gets these components without code. | L37: M4 | M37: M | N37: High | O37: #31 | Q37: OLD-99 | R37: UI component library | S37: No
A38: 37 | B38: Claude | C38: Component Library & Design System | D38: Safe rich-text editor (RTL/LTR) with HTML sanitization | E38: Feature | F38: Partial | G38: P2 | H38: A partial _RichTextEditorScripts.cshtml and HtmlSanitizer exist; they need standardizing and integration with the form builder. | I38: Turn it into a standard field type. | J38: A rich-text field in the form builder is sanitized on the server. | L38: M5 | M38: S | N38: Low | O38: #11 | P38: Titan #231 | R38: UI component library | S38: No
A39: 38 | B39: Claude | C39: Component Library & Design System | D39: Accessibility standard (contrast, focus, keyboard, labels, errors) | E39: Feature | F39: Not Started | G39: P1 | H39: Often required in enterprise and government contracts. 2026-10-28 plan audit: dependency/milestone corrected (see docs/audits/2026-10-28-dynamic-restful-audit.md). | I39: A checklist and automated axe tests in CI. | J39: Core components have no serious axe violations. | L39: M1 | M39: M | N39: Medium | O39: #31 | Q39: OLD-100 | R39: UI component library | S39: No
A40: 39 | B40: Claude | C40: Component Library & Design System | D40: Responsive QA matrix (desktop/tablet/mobile) for list, form, detail, dashboard, kanban | E40: Feature | F40: Not Started | G40: P1 | H40: A working mobile view for every screen type must be verified, not assumed. PEMS has manifest.json and service-worker.js. | I40: Matrix plus browser tests. | J40: No main page is broken at 375px. | L40: M4 | M40: M | N40: High | O40: #32 | P40: Titan #177 | Q40: OLD-102 | R40: UI component library | S40: No
...

Sheet Test Plan
A1: # | B1: Backlog row | C1: Area | D1: Feature | E1: Precondition | F1: Test steps (with expected result) | G1: Risk if it fails | H1: QA Status
A2: 1 | B2: 104 | C2: Licensing & Protection | D2: Full image restored on different hardware | E2: Active install with a valid licence on machine A; machine B with different hardware | F2: 1) Take a full disk image of machine A. 2) Restore and boot it on B. 3) Open the app. Expected: 'activation required' state, no domain module opens, a suspicious-event record is logged. | G2: Risk if it fails: If it opens, copy protection is worthless and on-prem sales are unprotected. | H2: Needs QA
A3: 2 | B3: 100 | C3: Licensing & Protection | D3: Full request-to-licence cycle | E3: Fresh install with no licence | F3: 1) Open the licence page and download the .pemsreq. 2) Issue a term licence with the vendor tool. 3) Upload it. Expected: activates with the right edition/modules. 4) Upload the same licence on a second install: it must be rejected. | G3: Risk if it fails: A transferable licence means lost revenue. | H3: Needs QA
A4: 3 | B4: 105 | C4: Licensing & Protection | D4: Setting the clock back | E4: A 30-day licence with 20 days consumed | F4: Set the system clock back 20 days and start the app. Expected: soft lock/clock-tamper warning; consumed days are not restored. | G4: Risk if it fails: Unlimited free renewal. | H4: Needs QA
A5: 4 | B5: 102 | C5: Licensing & Protection | D5: Licence type boundaries | E5: A term licence expiring tonight; a lifetime licence; a trial licence | F5: 1) Let the term licence reach its end date: the app drops to restricted mode. 2) Check expiry at Jalali midnight. 3) A lifetime licence shows no expiry warning. 4) Renew a term licence before and after expiry. | G5: Risk if it fails: An off-by-one error locks a legitimate customer. | H5: Needs QA
A6: 5 | B6: 116 | C6: Licensing & Protection | D6: Hardware replacement | E6: Active install | F6: Request a re-host, vendor approves, new licence; the old licence is disabled on the old machine. Exceeding the cap requires manual approval. | G6: Risk if it fails: A legitimate customer stays down after a server failure. | H6: Needs QA
A7: 6 | B7: 110 | C7: Licensing & Protection | D7: No bypass present | E7: Final release package | F7: Scan the package for bypass flags; boot without a licence in dev/staging/prod: all three lock. The allowlisted surfaces stay open. | G7: Risk if it fails: Selling an unlocked package. | H7: Needs QA
A8: 7 | B8: 106 | C8: Licensing & Protection | D8: Issuing tool only at the vendor | E8: Customer package | F8: Open the customer package: no issuing tool and no private key exist. | G8: Risk if it fails: Exposure of licence issuing. | H8: Needs QA
A9: 8 | B9: 10 | C9: Metadata Core & Dynamic Platform | D9: Create an entity purely with metadata | E9: Clean instance | F9: Create a 'lab sample' entity with 10 fields in the UI, publish, create/edit/delete a record with no deploy. Expected: list, form, search, export and audit work. | G9: Risk if it fails: The core of dynamism does not work. | H9: Needs QA
A10: 9 | B10: 13 | C10: Metadata Core & Dynamic Platform | D10: Field type change with data | E10: Entity with 100k records | F10: Change a field from text to number: risk preview, two-step approval, backup; then roll back. Expected: data returns intact. | G10: Risk if it fails: Loss of customer data. | H10: Needs QA
A11: 10 | B11: 12 | C11: Metadata Core & Dynamic Platform | D11: Server-side paging/filter | E11: 500k records | F11: Filter and sort the list; response under 500 ms. The total count respects RLS. | G11: Risk if it fails: Repeat of a known paging regression. | H11: Needs QA
A12: 11 | B12: 178 | C12: Access, RLS, Sessions & Security | D12: Data leakage | E12: Two users with different scope | F12: Read user A's record as user B through list, search, export, report, API and AI: it must never appear. | G12: Risk if it fails: Leak of customer confidential information. | H12: Needs QA
A13: 12 | B13: 44 | C13: Dynamic Form Builder | D13: Build an inspection form | E13: Builder role | F13: Build a 20-field form with 2 tabs, a child table and conditions; preview as different roles; publish. Create a second version: old records stay intact. | G13: Risk if it fails: A failed form builder means a failed product. | H13: Needs QA
... A34: 33 | B34: 336 | C34: DevOps, Source Control & Release Management | D34: plan-sync keeps plan and the issue tracker consistent | E34: A tracker project with the Plan ID field and CI secrets. | F34: Run export and push; change a status in the issue tracker; run pull and check. Expected: workbook status follows the issue tracker, check passes; a duplicate Plan ID or Done row without evidence fails. | G34: Risk if it fails: The plan file and the issue tracker disagree and developers lose trust in one of them. | H34: Needs QA

Sheet Roadmap
A1: Epic / Milestone | B1: When | C1: Priority | D1: Areas Involved | E1: Rationale | F1: Tasks
A2: M0 - Baseline and foundation decisions | B2: Now | C2: P0 | D2: FND, LIC, BRD, DEM, WEB, MIG, CMP, QA | E2: Without the decisions on storage, UI technology, libraries, the licensing threat model and editions nothing later is stable. Decisions are cheap and unblock everything. In parallel run a real build/test and clean secrets from the repo. | F2: =COUNTIF(Backlog!$L$2:$L$350,"M0")
A3: M1 - Dynamic core, components and licensing (Alpha) | B3: Now | C3: P0 | D3: DYN, CMP, LIC, SEC, LOC | E3: These block everything else: metadata registry, dynamic API with RLS, safe schema change, grid/form, Persian/Jalali, and the whole licence chain (fingerprint, install seal, request file, signed licence, vendor tool, anti-clone). Selling without a licence and without dynamism is meaningless. | F3: =COUNTIF(Backlog!$L$2:$L$350,"M1")
A4: M2 - Builders, demo and install (Beta) | B4: Next | C4: P0 | D4: FRM, MOD, WFL, MIG, DEM, INS, BRD | E4: The form, module and workflow builders plus the first migration wave (wave 1) prove the engine works. The demo and the installer with signed updates allow sales to begin. | F4: =COUNTIF(Backlog!$L$2:$L$350,"M2")
A5: M3 - Commercial release 1.0: demo, website, brand and legal | B5: Next | C5: P1 | D5: LIC, BRD, DEM, WEB, INS, DEV, CVM, HST | E5: Sellable packaging: licence activation portal, website, sales material, pilot customer, licence upgrade/transfer/renewal and support, plus the customer registry and release process needed before the first customer is live. | F5: =COUNTIF(Backlog!$L$2:$L$350,"M3")
A6: M4 - Platform completion and module migration | B6: Next | C6: P1 | D6: DYN, CMP, FRM, MOD, WFL, MIG, SEC, INT, QA, LOC, RPT, AI, OPS, EDM, EAM | E6: Release 1.0 must be able to host every wave: the rest of the platform P1 work, wave 2, mobile, SSO, security and the report builder. | F6: =COUNTIF(Backlog!$L$2:$L$350,"M4")
A7: M5 - Competitive features (P2) | B7: Later | C7: P2 | D7: All | E7: Capabilities that make selling easier but do not block 1.0. | F7: =COUNTIF(Backlog!$L$2:$L$350,"M5")
A8: M6 - Later (P3) | B8: Later | C8: P3 | D8: All | E8: Highest uncertainty and lowest sales impact. | F8: =COUNTIF(Backlog!$L$2:$L$350,"M6")
A10: Suggested order for the first 60 days (after owner approval)
A11: Week 1: F_BASE (real build/test), F_SECRET (repo secrets), F_ADR, and the F_STORE / F_UI / F_LIBS decisions with small prototypes.
A12: Weeks 1-2: owner decisions: VM/container policy (L_TIMES), edition matrix (L_EDITION), pricing (B_PRICE), legal structure (B_ENTITY).
A13: Weeks 2-4: L_MODEL (threat model) and L_FP + L_INSTALLID (proof: an image on other hardware does not run); C_AUDIT; M_AUDIT.
A14: Weeks 3-8: vertical slice: D_OBJ + D_API + C_GRID + FRM_RUN on one sample entity (migration wave 1 pilot); S_RLS in parallel.
A15: Weeks 5-8: L_REQ -> L_LICFMT -> L_VENDOR -> L_UI -> L_FIRSTRUN (the complete licence chain) and LOC_DEFAULT / LOC_CAL.
A16: End of 60 days: an internal demo of 'build a module in the UI and run it' with the machine-locked licence working; then M2.

Sheet Sprint 1
A1: Sprint 1 - commercial and dynamic-BPMS foundation
A2: Dates | B2: 2026-10-26 to 2026-11-06 (two weeks; adjust at import)
A3: Team | B3: Member A (product owner: decisions, business, approvals), Member B (developer: reviews and merges), the AI assistant (does most Claude-doer rows under their review)
A4: Goal | B4: Record the foundation decisions, prove the component technology, start the licensing and metadata-registry designs, make the build and the demo pipeline trustworthy, and protect the source and the signing key.
A5: Why now | B5: Commercial release needs licensing and a demo; the dynamic BPMS needs the metadata registry and the component library. Both start with decisions and designs that unblock the large XL rows.
A6: Capacity rule | B6: About 11 person-weeks nominal; 11 of 16 items are doable by the assistant, so humans mainly decide, review and merge. Stretch items start only when all committed items are in review.
A7: Definition of done | B7: The row's 'Done when' text is met, evidence is written in the Report column, tests/CHANGELOG/Supportability Matrix updated (Instructions rule 22), changes merged by pull request.
A8: Out of scope | B8: Implementation of the registry (#10), the licence code (#98+), the component library build (#322+) and page migration waves: they start after these designs and the spike.
A10: Plan ID | B10: Task | C10: Owner | D10: Doer | E10: Effort | F10: Priority | G10: Committed / stretch | H10: Done when
A11: 2 | B11: Create the architecture decision record (ADR) log in plan/adr and record the decisions already taken | C11: Member A | D11: Claude | E11: S | F11: P0 | G11: Committed | H11: Done when: plan/adr contains the template and six ADRs approved by Member A; every backlog row marked decided points to its ADR.
A12: 3 | B12: Write the one-page platform operating model: what is the dynamic engine, what are Domain Packs, what stays static | C12: Member A | D12: Claude | E12: M | F12: P0 | G12: Committed | H12: Done when: Member A approved the document; every module appears in exactly one class; rows #10, #85 and #94 reference it.
A13: 107 | B13: Define and perform the licence signing-key procedure (create keys offline, storage, backup, rotation, compromise plan) | C13: Member A | D13: User | E13: M | F13: P0 | G13: Committed | H13: Done when: the procedure is approved and followed; the public key is in the repository; a test signature verifies; the private key is not on any development machine.
A14: 257 | B14: Move the source code to a private company-owned GitHub organization with access control, branch protection and a backup | C14: Member A | D14: User | E14: M | F14: P0 | G14: Committed | H14: Done when: the repository is private; branch protection and 2FA are on; a backup job ran once; the member list with roles is recorded.
A15: 337 | B15: Finish the issue-tracker setup: board columns, Plan ID field, and the API token stored as a CI secret | C15: Member A | D15: User | E15: S | F15: P0 | G15: Committed | H15: Done when: a test import of the generated import file (python tools/plan-sync/plan_sync.py export) creates the epics and issues with Plan IDs and the Sprint 1 items; the bot token works from CI.
A16: 338 | B16: Design the metadata registry (apps, modules, entities, fields, relations, versions) and write the ADR | C16: Member A | D16: Claude | E16: M | F16: P0 | G16: Committed | H16: Done when: the design document and ADR exist; Member A and Member B have reviewed them; the sketched classes compile; open questions are listed with an owner; rows #10, #11, #13 and #28 reference the document.
A17: 339 | B17: Write the licensing technical design: machine fingerprint signals, install seal, request and licence file formats, verification points, vendor tool | C17: Member A | D17: Claude | E17: M | F17: P0 | G17: Committed | H17: Done when: the document covers rows #98-#106 with data formats and a sequence for first activation, renewal and restore-from-image; Member A approved it; each open risk names the contractual answer (EULA, #120).
A18: 1 | B18: Run the build and test suite once and store a baseline report (counts, duration, environment, every failing test) | C18: Member B | D18: Claude | E18: S | F18: P0 | G18: Committed | H18: Done when: plan/baseline/<date>.md exists with the numbers above; each failing test is listed with a cause; each real defect has its own backlog row. Known today (not yet in a report): LinuxDeploymentArtifactsTests LF check, a SQLEXPRESS-only sidebar test and ImportCenterNavigationTests (LetterCompose) fail on a clean main.
A19: 7 | B19: Make the build workflow fail on red tests and publish a versioned artifact on version tags | C19: Member B | D19: Claude | E19: M | F19: P0 | G19: Committed | H19: Done when: a red test fails the workflow; a tag produces a release artifact with version, commit and build number; no secret is stored in the repository.
A20: 9 | B20: Audit the repository, history and container files for secrets and unsafe defaults, and fix what remains | C20: Member B | D20: Claude | E20: S | F20: P0 | G20: Committed | H20: Done when: the report exists; HEAD is clean; every historical finding has a decision and an owner.
A21: 29 | B21: Finish the UI pattern audit: review the 30 heaviest pages by hand and compute the convertible percentage per migration wave | C21: Member B | D21: Claude | E21: M | F21: P0 | G21: Committed | H21: Done when: the audit document lists A/B/C for 30 pages and the percentage per wave W1-W5; the list of missing components feeds rows #322-#325.
A22: 30 | B22: Consolidate the design tokens into one file and remove hard-coded colours from the shared CSS | C22: Member B | D22: Claude | E22: M | F22: P0 | G22: Committed | H22: Done when: the four listed CSS files contain no hex colours and no physical left/right rules; screenshots show no visible change; the token file is documented in docs/design/WORKSPACE_DESIGN_SYSTEM.md.
... A27: 340 | B27: Make the demo site start: issue the TLS certificate and diagnose why the application does not answer after the first deploy | C27: Member B | D27: Claude | E27: M | F27: P0 | G27: Committed | H27: Done when: https://demo.parmisata.ir opens with a valid certificate; /health/database returns UpToDate; the demo workflow run is green end to end; the cause and fix are written in docs/deployment/DEMO_DEPLOYMENT.md.

Sheet Licensing Design
A1: PEMS licensing design - machine and install-time locked (on-prem, offline)
A2: Owner need: even if a whole machine is imaged and deployed elsewhere it must not work; a file is generated on the customer server, returned to us, and we deliver the real licence; lifetime or timed. Limits: no offline scheme is unbreakable - the goal is to defeat casual copying and add contractual backing.
A4: Step | B4: Stage | C4: Description | D4: Backlog rows
A5: 1 | B5: Install | C5: The installer runs; first start creates a random Install ID and a key pair; the private key is made non-exportable with DPAPI/TPM; install time and a monotonic counter are written to the 'install seal' (DB + an independent file). | D5: #99
A6: 2 | B6: Request | C6: Without a licence the system starts in 'activation required' mode and creates a .pemsreq file: hashed fingerprint, Install ID, install time, version, customer id, nonce, install-key signature. | D6: #98 #100 #108
A7: 3 | B7: Return to vendor | C7: The customer gives the file to us through the website portal (WEB_ACT) or by hand; the product itself never calls out. | D7: #161 #123
A8: 4 | B8: Issue | C8: The vendor tool (L_VENDOR) validates the signature and structure, selects edition/modules/limits/type (lifetime or term) and signs a .pemslic with the offline private key; the licence is bound to the nonce, Install ID and fingerprint hash of that request. | D8: #101 #102 #106 #107
